# Lesson 2.3: Homegrown Exceptions Pt. 2

In the previous lesson, you probably made a `raise` function that looks like this:

```javascript
function raise() {
  return "Fail!"
}
```

or this

```javascript
function raise() {
  return null;
}
```

And you probably made a `tryWith` function that looks like this:

```javascript
function tryWith(result) {
  if (result === "Fail!") { // or null
    return "Error!";
  } else {
    return result;
  }
}
```

It's clear that this is not exactly the most sophisticated of implementations. Some might even call it a hack! The downsides of this approach are obvious. For starters, lots of things, not just our `raise` function, return `"Fail!"`, so we might catch an excetion where none actually existed.

Instead of using strings or `null` values or whatever, what if we had a custom object for exceptions? Fortunately, we can make our own homegrown custom class called `Exn`:

```javascript
class Exn {}

function raise() {
  return new Exn(); 
}
```

Then on the `tryWith` side of things, we can write:

```javascript
function tryWith(result) {
  // We use instanceof to determine if the result is an Exn object
  if (result instanceof Exn) {
    return "Error";
  } else {
    return result;
  }
}
```

**Problem 2.2.0:** Use this new kind of exception (with the `Exn` class) in the `tryDivide` method.

```problem
///// CODE
class Exn {}

function raise() {
  return new Exn();
}

function tryWith(result) {
  if (result instanceof Exn) {
    return "Error";
  } else {
    return result;
  }
}

function tryDivide(x, y) {
  // TODO: Your code here 
}

///// SOLUTION
class Exn {}

function raise() {
  return new Exn();
}

function tryWith(result) {
  if (result instanceof Exn) {
    return "Error";
  } else {
    return result;
  }
}

function tryDivide(x, y) {
  if (y === 0) {
    return raise();
  } else {
    return x / y;
  }
}

///// TESTS
tryDivide(1, 0).constructor.name ==> "Exn"
tryWith(tryDivide(10, 2)) ==> 5
tryWith(tryDivide(100, -100)) ==> -1
tryWith(tryDivide(134, 0)) ==> "Error"

///// LANGUAGE
JavaScript
```

**Problem 2.2.1:** One of the features JavaScript's `Error` objects have that `Exn` doesn't is that it has a `message` property for error messages. What if we added that feature to `Exn`? Add a `message` field to the `Exn` class, and modify `raise` and `tryWith` to make use of the upgraded `Exn`s. Make sure to follow the comments!

```problem
///// CODE
// Change Exn so it now has a message property
class Exn {
  // TODO: Your code here
}

// Change raise to take in your error message as an argument
function raise(???) {
  // TODO: Your code here
}

// Change tryWith to return the error message upon catching an exception
function tryWith(result) {
  // TODO: Your code here 
}

// Change tryDivide to use the new Exn class
// If a division by zero is encountered, tryDivide should throw
// an exception with the message "Division by zero encountered!"
function tryDivide(x, y) {
  // TODO: Your code here
}

///// SOLUTION
class Exn {
  constructor(message) {
    this.message = message;
  }
}

function raise(message) {
  return new Exn(message);
}

function tryWith(result) {
  if (result instanceof Exn) {
    return result.message;
  } else {
    return result;
  }
}

function tryDivide(x, y) {
  if (y === 0) {
    return raise("Division by zero encountered!"); 
  } else {
    return x / y;
  }
}

///// TESTS
raise("Message").constructor.name ==> "Exn"
raise("Message").message ==> "Message"
tryWith(2) ==> 2
tryWith("FooBar") ==> "FooBar"
tryWith(raise("Uh oh!")) ==> "Uh oh!"
tryDivide(2, 2) ==> 1
tryDivide(2, 0).constructor.name ==> "Exn"
tryDivide(2, 0).message ==> "Division by zero encountered!"
tryWith(tryDivide(2, 0)) ==> "Division by zero encountered!"

///// LANGUAGE
JavaScript
```

**Problem 2.2.2:** Printing out the error messages inside `Exn` is fun, but it's not the only thing we can do with them.

Modify `tryWith` so that in addition to the result, it also takes in a function `func` that is called when `tryWith` catches an exception. Then `func` will take in `Exn.message` as its single argument, do whatever it wants with it, and returns a result.

```problem
///// CODE
class Exn {
  // TODO: Copy-paste from above 
}

// Change raise to take in your error message as an argument
function raise(???) {
  // TODO: Copy-paste from above 
}

// New argument!
function tryWith(result, func) { 
  // TODO: Your code here
}

///// SOLUTION
class Exn {
  constructor(message) {
    this.message = message;
  }
}

function raise(message) {
  return new Exn(message);
}

function tryWith(result, func) {
  if (result instanceof Exn) {
    return func(result.message);
  } else {
    return result;
  }
}

///// TESTS
raise().constructor.name ==> "Exn"
tryWith(raise(""), msg => { return "Oops!"; }) ==> "Oops!"
tryWith(2, msg => { return "Oops!"; }) ==> 2
tryWith(raise("Foo"), msg => { return msg; }) ==> "Foo"
tryWith(raise("Oh no"), msg => { return msg + "!!!"; }) ==> "Oh no!!!"

///// LANGUAGE
JavaScript
```